<mujoco model="GEN72_robotiq2f85">
  <compiler angle="radian" meshdir="GEN72_with_gripper_assets" autolimits="true"/>

  <option gravity="0 0 -9.81" timestep="0.001" cone="elliptic" impratio="10"/>

  <visual>
    <headlight ambient="0.5 0.5 0.5" diffuse="0.8 0.8 0.8" specular="0.3 0.3 0.3"/>
    <scale framewidth="0.01" framelength="0.3"/>
  </visual>

  <default>
    <default class="2f85">
      <mesh scale="0.001 0.001 0.001"/>
      <general biastype="affine"/>
      <joint axis="1 0 0"/>
      <default class="driver">
        <joint range="0 0.8" armature="0.005" damping="0.1" solimplimit="0.95 0.99 0.001" solreflimit="0.005 1"/>
      </default>
      <default class="follower">
        <joint range="-0.872664 0.872664" armature="0.001" pos="0 -0.018 0.0065" solimplimit="0.95 0.99 0.001" solreflimit="0.005 1"/>
      </default>
      <default class="spring_link">
        <joint range="-0.29670597283 0.8" armature="0.001" stiffness="0.05" springref="2.62" damping="0.00125"/>
      </default>
      <default class="coupler">
        <joint range="-1.57 0" armature="0.001" solimplimit="0.95 0.99 0.001" solreflimit="0.005 1"/>
      </default>
      <default class="gripper_visual">
        <geom type="mesh" contype="0" conaffinity="0" group="2"/>
      </default>
      <default class="gripper_collision">
        <geom type="mesh" group="3"/>
        <default class="pad_box1">
          <geom mass="0" type="box" pos="0 -0.0026 0.028125" size="0.011 0.004 0.009375" friction="0.7"
            solimp="0.95 0.99 0.001" solref="0.004 1" priority="1" rgba="0.55 0.55 0.55 1"/>
        </default>
        <default class="pad_box2">
          <geom mass="0" type="box" pos="0 -0.0026 0.009375" size="0.011 0.004 0.009375" friction="0.6"
            solimp="0.95 0.99 0.001" solref="0.004 1" priority="1" rgba="0.45 0.45 0.45 1"/>
        </default>
      </default>
    </default>
  </default>

  <asset>
    <texture name="grid" type="2d" builtin="checker" width="512" height="512" rgb1="0.2 0.3 0.4" rgb2="0.3 0.4 0.5"/>
    <material name="grid" texture="grid" texrepeat="10 10" reflectance="0.1"/>

    <!-- GEN72 arm meshes -->
    <mesh name="base_link" file="base_link.STL"/>
    <mesh name="Link1" file="Link1.STL"/>
    <mesh name="Link2" file="Link2.STL"/>
    <mesh name="Link3" file="Link3.STL"/>
    <mesh name="Link4" file="Link4.STL"/>
    <mesh name="Link5" file="Link5.STL"/>
    <mesh name="Link6" file="Link6.STL"/>
    <mesh name="Link7" file="Link7.STL"/>

    <!-- Robotiq 2F-85 materials -->
    <material name="gripper_metal" rgba="0.58 0.58 0.58 1"/>
    <material name="gripper_silicone" rgba="0.1882 0.1882 0.1882 1"/>
    <material name="gripper_gray" rgba="0.4627 0.4627 0.4627 1"/>
    <material name="gripper_black" rgba="0.149 0.149 0.149 1"/>

    <!-- Robotiq 2F-85 meshes -->
    <mesh class="2f85" file="base_mount.stl"/>
    <mesh class="2f85" name="gripper_base" file="base.stl"/>
    <mesh class="2f85" file="driver.stl"/>
    <mesh class="2f85" file="coupler.stl"/>
    <mesh class="2f85" file="follower.stl"/>
    <mesh class="2f85" file="pad.stl"/>
    <mesh class="2f85" file="silicone_pad.stl"/>
    <mesh class="2f85" file="spring_link.stl"/>
  </asset>

  <worldbody>
    <light pos="0 0 3" dir="0 0 -1" diffuse="0.8 0.8 0.8" specular="0.3 0.3 0.3"/>
    <light pos="2 2 3" dir="-1 -1 -1" diffuse="0.5 0.5 0.5"/>
    <geom name="floor" type="plane" size="3 3 0.1" material="grid"/>

    <!-- Graspable cylinder -->
    <body name="cylinder" pos="0.455 0.0 0.04">
      <freejoint name="cylinder_joint"/>
      <geom name="cylinder_geom" type="cylinder" size="0.04 0.04" rgba="1 0.3 0.1 1" mass="0.1"
        friction="1.5 0.5 0.01" solimp="0.95 0.99 0.001" solref="0.004 1" condim="4" priority="1"/>
    </body>

    <!-- GEN72 Robot Arm -->
    <geom type="mesh" rgba="1 1 1 1" mesh="base_link"/>
    <body name="Link1" pos="0 0 0.218">
      <inertial pos="3.54242e-07 -6.04073e-05 -0.0474562" quat="0.707095 0.00082527 -0.000815443 0.707117" mass="0.511232" diaginertia="0.0010204 0.000959441 0.000388711"/>
      <joint name="joint1" pos="0 0 0" axis="0 0 1" range="-3.0014 3.0014" damping="10" actuatorfrcrange="-100 100"/>
      <geom type="mesh" rgba="1 1 1 1" mesh="Link1"/>
      <body name="Link2" quat="0.707105 -0.707108 0 0">
        <inertial pos="-7.09648e-07 -0.0576246 -3.8844e-05" quat="0.707724 0.706489 -3.66761e-05 2.79347e-05" mass="0.551907" diaginertia="0.0014214 0.00127235 0.000525712"/>
        <joint name="joint2" pos="0 0 0" axis="0 0 1" range="-1.8323 1.8323" damping="10" actuatorfrcrange="-100 100"/>
        <geom type="mesh" rgba="1 1 1 1" mesh="Link2"/>
        <body name="Link3" pos="0 -0.28 0" quat="0.707105 0.707108 0 0">
          <inertial pos="0.00897441 2.62634e-05 -0.0738285" quat="0.989785 -0.000620494 0.142566 -0.00106265" mass="0.77413" diaginertia="0.00256503 0.00248694 0.000756989"/>
          <joint name="joint3" pos="0 0 0" axis="0 0 1" range="-3.0014 3.0014" damping="10" actuatorfrcrange="-100 100"/>
          <geom type="mesh" rgba="1 1 1 1" mesh="Link3"/>
          <body name="Link4" pos="0.04 0 0" quat="0.707105 0.707108 0 0">
            <inertial pos="-0.00962439 0.0352034 0.000174576" quat="0.439439 0.552618 -0.438956 0.55572" mass="0.43713" diaginertia="0.000952335 0.000901816 0.00023284"/>
            <joint name="joint4" pos="0 0 0" axis="0 0 1" range="-2.8792 0.9597" damping="10" actuatorfrcrange="-100 100"/>
            <geom type="mesh" rgba="1 1 1 1" mesh="Link4"/>
            <body name="Link5" pos="-0.019 0.2525 0" quat="0.707105 -0.707108 0 0">
              <inertial pos="-4.77957e-07 -3.84738e-05 -0.0669555" quat="1 0.000543145 1.00595e-05 4.16479e-05" mass="0.424277" diaginertia="0.00112445 0.00103382 0.000274639"/>
              <joint name="joint5" pos="0 0 0" axis="0 0 1" range="-3.0014 3.0014" damping="5" actuatorfrcrange="-50 50"/>
              <geom type="mesh" rgba="1 1 1 1" mesh="Link5"/>
              <body name="Link6" quat="0.707105 0.707108 0 0">
                <inertial pos="0.00184222 0.0379763 -9.21091e-05" quat="0.576988 0.408739 -0.576994 0.408774" mass="0.302793" diaginertia="0.000155721 0.00014117 0.000131576"/>
                <joint name="joint6" pos="0 0 0" axis="0 0 1" range="-1.707 1.783" damping="5" actuatorfrcrange="-50 50"/>
                <geom type="mesh" rgba="1 1 1 1" mesh="Link6"/>
                <body name="Link7" pos="0.0905 0.067 0" quat="0.499998 0.5 0.500002 0.5">
                  <inertial pos="0.000199885 -4.25082e-08 -0.0292499" quat="0.081641 0.702378 -0.081641 0.702378" mass="0.176613" diaginertia="8.48643e-05 6.24292e-05 6.24281e-05"/>
                  <joint name="joint7" pos="0 0 0" axis="0 0 1" range="-3.0014 3.0014" damping="5" actuatorfrcrange="-50 50"/>
                  <geom type="mesh" rgba="1 1 1 1" mesh="Link7"/>

                  <!-- ============ Robotiq 2F-85 Gripper ============ -->
                  <body name="gripper_mount" pos="0 0 -0.055" childclass="2f85">
                    <body name="base_mount" pos="0 0 0.007">
                      <geom class="gripper_visual" mesh="base_mount" material="gripper_black"/>
                      <geom class="gripper_collision" mesh="base_mount"/>
                      <body name="gripper_base" pos="0 0 0.0038" quat="1 0 0 -1">
                        <inertial mass="0.777441" pos="0 -2.70394e-05 0.0354675" quat="1 -0.00152849 0 0"
                          diaginertia="0.000260285 0.000225381 0.000152708"/>
                        <geom class="gripper_visual" mesh="gripper_base" material="gripper_black"/>
                        <geom class="gripper_collision" mesh="gripper_base"/>
                        <site name="pinch" pos="0 0 0.145" type="sphere" group="5" rgba="0.9 0.9 0.9 1" size="0.005"/>

                        <!-- Right-hand side 4-bar linkage -->
                        <body name="right_driver" pos="0 0.0306011 0.054904">
                          <inertial mass="0.00899563" pos="2.96931e-12 0.0177547 0.00107314" quat="0.681301 0.732003 0 0"
                            diaginertia="1.72352e-06 1.60906e-06 3.22006e-07"/>
                          <joint name="right_driver_joint" class="driver"/>
                          <geom class="gripper_visual" mesh="driver" material="gripper_gray"/>
                          <geom class="gripper_collision" mesh="driver"/>
                          <body name="right_coupler" pos="0 0.0315 -0.0041">
                            <inertial mass="0.0140974" pos="0 0.00301209 0.0232175" quat="0.705636 -0.0455904 0.0455904 0.705636"
                              diaginertia="4.16206e-06 3.52216e-06 8.88131e-07"/>
                            <joint name="right_coupler_joint" class="coupler"/>
                            <geom class="gripper_visual" mesh="coupler" material="gripper_black"/>
                            <geom class="gripper_collision" mesh="coupler"/>
                          </body>
                        </body>
                        <body name="right_spring_link" pos="0 0.0132 0.0609">
                          <inertial mass="0.0221642" pos="-8.65005e-09 0.0181624 0.0212658" quat="0.663403 -0.244737 0.244737 0.663403"
                            diaginertia="8.96853e-06 6.71733e-06 2.63931e-06"/>
                          <joint name="right_spring_link_joint" class="spring_link"/>
                          <geom class="gripper_visual" mesh="spring_link" material="gripper_black"/>
                          <geom class="gripper_collision" mesh="spring_link"/>
                          <body name="right_follower" pos="0 0.055 0.0375">
                            <inertial mass="0.0125222" pos="0 -0.011046 0.0124786" quat="1 0.1664 0 0"
                              diaginertia="2.67415e-06 2.4559e-06 6.02031e-07"/>
                            <joint name="right_follower_joint" class="follower"/>
                            <geom class="gripper_visual" mesh="follower" material="gripper_black"/>
                            <geom class="gripper_collision" mesh="follower"/>
                            <body name="right_pad" pos="0 -0.0189 0.01352">
                              <geom class="pad_box1" name="right_pad1"/>
                              <geom class="pad_box2" name="right_pad2"/>
                              <inertial mass="0.0035" pos="0 -0.0025 0.0185" quat="0.707107 0 0 0.707107"
                                diaginertia="4.73958e-07 3.64583e-07 1.23958e-07"/>
                              <geom class="gripper_visual" mesh="pad"/>
                              <body name="right_silicone_pad">
                                <geom class="gripper_visual" mesh="silicone_pad" material="gripper_black"/>
                              </body>
                            </body>
                          </body>
                        </body>

                        <!-- Left-hand side 4-bar linkage -->
                        <body name="left_driver" pos="0 -0.0306011 0.054904" quat="0 0 0 1">
                          <inertial mass="0.00899563" pos="0 0.0177547 0.00107314" quat="0.681301 0.732003 0 0"
                            diaginertia="1.72352e-06 1.60906e-06 3.22006e-07"/>
                          <joint name="left_driver_joint" class="driver"/>
                          <geom class="gripper_visual" mesh="driver" material="gripper_gray"/>
                          <geom class="gripper_collision" mesh="driver"/>
                          <body name="left_coupler" pos="0 0.0315 -0.0041">
                            <inertial mass="0.0140974" pos="0 0.00301209 0.0232175" quat="0.705636 -0.0455904 0.0455904 0.705636"
                              diaginertia="4.16206e-06 3.52216e-06 8.88131e-07"/>
                            <joint name="left_coupler_joint" class="coupler"/>
                            <geom class="gripper_visual" mesh="coupler" material="gripper_black"/>
                            <geom class="gripper_collision" mesh="coupler"/>
                          </body>
                        </body>
                        <body name="left_spring_link" pos="0 -0.0132 0.0609" quat="0 0 0 1">
                          <inertial mass="0.0221642" pos="-8.65005e-09 0.0181624 0.0212658" quat="0.663403 -0.244737 0.244737 0.663403"
                            diaginertia="8.96853e-06 6.71733e-06 2.63931e-06"/>
                          <joint name="left_spring_link_joint" class="spring_link"/>
                          <geom class="gripper_visual" mesh="spring_link" material="gripper_black"/>
                          <geom class="gripper_collision" mesh="spring_link"/>
                          <body name="left_follower" pos="0 0.055 0.0375">
                            <inertial mass="0.0125222" pos="0 -0.011046 0.0124786" quat="1 0.1664 0 0"
                              diaginertia="2.67415e-06 2.4559e-06 6.02031e-07"/>
                            <joint name="left_follower_joint" class="follower"/>
                            <geom class="gripper_visual" mesh="follower" material="gripper_black"/>
                            <geom class="gripper_collision" mesh="follower"/>
                            <body name="left_pad" pos="0 -0.0189 0.01352">
                              <geom class="pad_box1" name="left_pad1"/>
                              <geom class="pad_box2" name="left_pad2"/>
                              <inertial mass="0.0035" pos="0 -0.0025 0.0185" quat="1 0 0 1"
                                diaginertia="4.73958e-07 3.64583e-07 1.23958e-07"/>
                              <geom class="gripper_visual" mesh="pad"/>
                              <body name="left_silicone_pad">
                                <geom class="gripper_visual" mesh="silicone_pad" material="gripper_black"/>
                              </body>
                            </body>
                          </body>
                        </body>
                      </body>
                    </body>
                  </body>
                  <!-- ============ End Gripper ============ -->

                </body>
              </body>
            </body>
          </body>
        </body>
      </body>
    </body>
  </worldbody>

  <!-- Gripper contact exclusions -->
  <contact>
    <exclude body1="gripper_base" body2="left_driver"/>
    <exclude body1="gripper_base" body2="right_driver"/>
    <exclude body1="gripper_base" body2="left_spring_link"/>
    <exclude body1="gripper_base" body2="right_spring_link"/>
    <exclude body1="right_coupler" body2="right_follower"/>
    <exclude body1="left_coupler" body2="left_follower"/>
  </contact>

  <!-- Gripper tendon: synchronize left and right driver joints -->
  <tendon>
    <fixed name="split">
      <joint joint="right_driver_joint" coef="0.5"/>
      <joint joint="left_driver_joint" coef="0.5"/>
    </fixed>
  </tendon>

  <!-- Gripper equality constraints: 4-bar linkage + symmetry -->
  <equality>
    <connect anchor="0 0 0" body1="right_follower" body2="right_coupler" solimp="0.95 0.99 0.001" solref="0.005 1"/>
    <connect anchor="0 0 0" body1="left_follower" body2="left_coupler" solimp="0.95 0.99 0.001" solref="0.005 1"/>
    <joint joint1="right_driver_joint" joint2="left_driver_joint" polycoef="0 1 0 0 0" solimp="0.95 0.99 0.001"
      solref="0.005 1"/>
  </equality>

  <actuator>
    <!-- GEN72 arm position actuators -->
    <position name="actuator_joint1" joint="joint1" kp="800" ctrlrange="-3.0014 3.0014"/>
    <position name="actuator_joint2" joint="joint2" kp="800" ctrlrange="-1.8323 1.8323"/>
    <position name="actuator_joint3" joint="joint3" kp="800" ctrlrange="-3.0014 3.0014"/>
    <position name="actuator_joint4" joint="joint4" kp="800" ctrlrange="-2.8792 0.9597"/>
    <position name="actuator_joint5" joint="joint5" kp="400" ctrlrange="-3.0014 3.0014"/>
    <position name="actuator_joint6" joint="joint6" kp="400" ctrlrange="-1.707 1.783"/>
    <position name="actuator_joint7" joint="joint7" kp="400" ctrlrange="-3.0014 3.0014"/>

    <!-- Robotiq 2F-85: single actuator controlling both fingers via tendon -->
    <general class="2f85" name="fingers_actuator" tendon="split" forcerange="-5 5" ctrlrange="0 255"
      gainprm="0.3137255 0 0" biasprm="0 -100 -10"/>
  </actuator>

  <keyframe>
    <key name="home" qpos="0.455 0.0 0.04 1 0 0 0 0 0 0 0 0 0 0 0 0 0 0 0 0 0 0"
         ctrl="0 0 0 0 0 0 0 0"/>
    <!-- cylinder: radius=0.23, half-height=0.04 -->
  </keyframe>
</mujoco>
